Traceback (most recent call last):
  File "/Users/tim/Data Science/Projects/Data Science Jobs/scripts/./add_info.py", line 128, in <module>
    ] = add_info(jobs_new.loc[i, "Link"])
        ^^^^^^^^^^^^^^^^^^^^^^^^^^^^^^^^^
  File "/Users/tim/Data Science/Projects/Data Science Jobs/scripts/./add_info.py", line 18, in add_info
    driver.get(url)
  File "/Library/Frameworks/Python.framework/Versions/3.11/lib/python3.11/site-packages/selenium/webdriver/remote/webdriver.py", line 356, in get
    self.execute(Command.GET, {"url": url})
  File "/Library/Frameworks/Python.framework/Versions/3.11/lib/python3.11/site-packages/selenium/webdriver/remote/webdriver.py", line 347, in execute
    self.error_handler.check_response(response)
  File "/Library/Frameworks/Python.framework/Versions/3.11/lib/python3.11/site-packages/selenium/webdriver/remote/errorhandler.py", line 229, in check_response
    raise exception_class(message, screen, stacktrace)
selenium.common.exceptions.TimeoutException: Message: Navigation timed out after 300000 ms
Stacktrace:
RemoteError@chrome://remote/content/shared/RemoteError.sys.mjs:8:8
WebDriverError@chrome://remote/content/shared/webdriver/Errors.sys.mjs:189:5
TimeoutError@chrome://remote/content/shared/webdriver/Errors.sys.mjs:691:5
bail@chrome://remote/content/marionette/sync.sys.mjs:211:19

